2025-10-31 18:56:40,503 ERROR: Unhandled Error: radiology_pdf_viewer.html [in C:\xampp\htdocs\INFO\error_handlers.py:53]
2025-10-31 18:56:40,869 ERROR: Traceback (most recent call last):
  File "C:\xampp\htdocs\INFO\.venv\lib\site-packages\flask\app.py", line 917, in full_dispatch_request
    rv = self.dispatch_request()
  File "C:\xampp\htdocs\INFO\.venv\lib\site-packages\flask\app.py", line 902, in dispatch_request
    return self.ensure_sync(self.view_functions[rule.endpoint])(**view_args)  # type: ignore[no-any-return]
  File "C:\xampp\htdocs\INFO\app.py", line 158, in decorated_function
    return f(*args, **kwargs)
  File "C:\xampp\htdocs\INFO\app.py", line 2764, in view_radiology
    return render_template('radiology_pdf_viewer.html', file_url=url_for('view_radiology', file_id=file_id))
  File "C:\xampp\htdocs\INFO\.venv\lib\site-packages\flask\templating.py", line 149, in render_template
    template = app.jinja_env.get_or_select_template(template_name_or_list)
  File "C:\xampp\htdocs\INFO\.venv\lib\site-packages\jinja2\environment.py", line 1087, in get_or_select_template
    return self.get_template(template_name_or_list, parent, globals)
  File "C:\xampp\htdocs\INFO\.venv\lib\site-packages\jinja2\environment.py", line 1016, in get_template
    return self._load_template(name, globals)
  File "C:\xampp\htdocs\INFO\.venv\lib\site-packages\jinja2\environment.py", line 975, in _load_template
    template = self.loader.load(self, name, self.make_globals(globals))
  File "C:\xampp\htdocs\INFO\.venv\lib\site-packages\jinja2\loaders.py", line 126, in load
    source, filename, uptodate = self.get_source(environment, name)
  File "C:\xampp\htdocs\INFO\.venv\lib\site-packages\flask\templating.py", line 65, in get_source
    return self._get_source_fast(environment, template)
  File "C:\xampp\htdocs\INFO\.venv\lib\site-packages\flask\templating.py", line 99, in _get_source_fast
    raise TemplateNotFound(template)
jinja2.exceptions.TemplateNotFound: radiology_pdf_viewer.html
 [in C:\xampp\htdocs\INFO\error_handlers.py:54]
2025-10-31 18:56:40,956 INFO: Accessing patient dashboard. Session data: {'_permanent': True, 'username': 'ahmed', 'role': 'patient', '_flashes': [('danger', 'An unexpected error occurred. Please try again later.')]} [in C:\xampp\htdocs\INFO\app.py:2108]
2025-10-31 18:56:40,969 INFO: Successfully loaded dashboard for patient: ahmed [in C:\xampp\htdocs\INFO\app.py:2186]
2025-10-31 18:57:18,387 ERROR: Unhandled Error: radiology_pdf_viewer.html [in C:\xampp\htdocs\INFO\error_handlers.py:53]
2025-10-31 18:57:18,389 ERROR: Traceback (most recent call last):
  File "C:\xampp\htdocs\INFO\.venv\lib\site-packages\flask\app.py", line 917, in full_dispatch_request
    rv = self.dispatch_request()
  File "C:\xampp\htdocs\INFO\.venv\lib\site-packages\flask\app.py", line 902, in dispatch_request
    return self.ensure_sync(self.view_functions[rule.endpoint])(**view_args)  # type: ignore[no-any-return]
  File "C:\xampp\htdocs\INFO\app.py", line 158, in decorated_function
    return f(*args, **kwargs)
  File "C:\xampp\htdocs\INFO\app.py", line 2764, in view_radiology
    return render_template('radiology_pdf_viewer.html', file_url=url_for('view_radiology', file_id=file_id))
  File "C:\xampp\htdocs\INFO\.venv\lib\site-packages\flask\templating.py", line 149, in render_template
    template = app.jinja_env.get_or_select_template(template_name_or_list)
  File "C:\xampp\htdocs\INFO\.venv\lib\site-packages\jinja2\environment.py", line 1087, in get_or_select_template
    return self.get_template(template_name_or_list, parent, globals)
  File "C:\xampp\htdocs\INFO\.venv\lib\site-packages\jinja2\environment.py", line 1016, in get_template
    return self._load_template(name, globals)
  File "C:\xampp\htdocs\INFO\.venv\lib\site-packages\jinja2\environment.py", line 975, in _load_template
    template = self.loader.load(self, name, self.make_globals(globals))
  File "C:\xampp\htdocs\INFO\.venv\lib\site-packages\jinja2\loaders.py", line 126, in load
    source, filename, uptodate = self.get_source(environment, name)
  File "C:\xampp\htdocs\INFO\.venv\lib\site-packages\flask\templating.py", line 65, in get_source
    return self._get_source_fast(environment, template)
  File "C:\xampp\htdocs\INFO\.venv\lib\site-packages\flask\templating.py", line 99, in _get_source_fast
    raise TemplateNotFound(template)
jinja2.exceptions.TemplateNotFound: radiology_pdf_viewer.html
 [in C:\xampp\htdocs\INFO\error_handlers.py:54]
2025-10-31 18:57:18,472 INFO: Accessing patient dashboard. Session data: {'_permanent': True, 'username': 'ahmed', 'role': 'patient', '_flashes': [('danger', 'An unexpected error occurred. Please try again later.')]} [in C:\xampp\htdocs\INFO\app.py:2108]
2025-10-31 18:57:18,477 INFO: Successfully loaded dashboard for patient: ahmed [in C:\xampp\htdocs\INFO\app.py:2186]
2025-10-31 18:57:35,586 WARNING: Watermarking failed for uploads\radiology\27\brain_mRI\1761929854_1_no.jpeg.tmp: 'ImageDraw' object has no attribute 'textsize' [in C:\xampp\htdocs\INFO\app.py:2444]
2025-10-31 18:57:35,600 ERROR: MRI analysis failed: Image file not found: uploads\radiology\27\brain_mRI\1761929854_1_no.jpeg [in C:\xampp\htdocs\INFO\app.py:2603]
2025-10-31 19:07:34,888 WARNING: Watermarking failed for uploads\radiology\27\brain_mRI\1761930454_1_no.jpeg.tmp: 'ImageDraw' object has no attribute 'textsize' [in C:\xampp\htdocs\INFO\app.py:2444]
2025-10-31 19:07:34,890 ERROR: MRI analysis failed: Image file not found: uploads\radiology\27\brain_mRI\1761930454_1_no.jpeg [in C:\xampp\htdocs\INFO\app.py:2640]
2025-10-31 19:08:13,689 WARNING: Watermarking failed for uploads\radiology\27\brain_mRI2\1761930493_Y2.jpg.tmp: 'ImageDraw' object has no attribute 'textsize' [in C:\xampp\htdocs\INFO\app.py:2444]
2025-10-31 19:08:13,692 ERROR: MRI analysis failed: Image file not found: uploads\radiology\27\brain_mRI2\1761930493_Y2.jpg [in C:\xampp\htdocs\INFO\app.py:2640]
2025-10-31 19:10:58,608 WARNING: Watermarking failed for uploads\radiology\27\brain_mRI2\1761930658_Y3.jpg.tmp: 'ImageDraw' object has no attribute 'textsize' [in C:\xampp\htdocs\INFO\app.py:2444]
2025-10-31 19:10:58,613 ERROR: MRI analysis failed: Image file not found: uploads\radiology\27\brain_mRI2\1761930658_Y3.jpg [in C:\xampp\htdocs\INFO\app.py:2640]
2025-10-31 19:12:03,487 ERROR: Error zipping folder: [WinError 2] The system cannot find the file specified: 'uploads\\radiology\\27\\brain_mRI2\\1761930493_Y2.jpg' [in C:\xampp\htdocs\INFO\app.py:2746]
2025-10-31 19:45:10,294 INFO: Accessing patient dashboard. Session data: {'_permanent': True, 'username': 'ahmed', 'role': 'patient'} [in C:\xampp\htdocs\INFO\app.py:2108]
2025-10-31 19:45:10,336 INFO: Successfully loaded dashboard for patient: ahmed [in C:\xampp\htdocs\INFO\app.py:2186]
2025-10-31 22:20:21,789 ERROR: Unhandled Error: (2002, "Can't connect to server on 'localhost' (10061)") [in C:\xampp\htdocs\INFO\error_handlers.py:53]
2025-10-31 22:20:21,790 ERROR: Unhandled Error: (2002, "Can't connect to server on 'localhost' (10061)") [in C:\xampp\htdocs\INFO\error_handlers.py:53]
2025-10-31 22:20:21,913 ERROR: Traceback (most recent call last):
  File "C:\xampp\htdocs\INFO\.venv\lib\site-packages\flask\app.py", line 915, in full_dispatch_request
    rv = self.preprocess_request()
  File "C:\xampp\htdocs\INFO\.venv\lib\site-packages\flask\app.py", line 1291, in preprocess_request
    rv = self.ensure_sync(before_func)()
  File "C:\xampp\htdocs\INFO\app.py", line 196, in before_request
    cur = mysql.connection.cursor()
  File "C:\xampp\htdocs\INFO\.venv\lib\site-packages\flask_mysqldb\__init__.py", line 109, in connection
    ctx.mysql_db = self.connect
  File "C:\xampp\htdocs\INFO\.venv\lib\site-packages\flask_mysqldb\__init__.py", line 97, in connect
    return MySQLdb.connect(**kwargs)
  File "C:\xampp\htdocs\INFO\.venv\lib\site-packages\MySQLdb\__init__.py", line 121, in Connect
    return Connection(*args, **kwargs)
  File "C:\xampp\htdocs\INFO\.venv\lib\site-packages\MySQLdb\connections.py", line 200, in __init__
    super().__init__(*args, **kwargs2)
MySQLdb.OperationalError: (2002, "Can't connect to server on 'localhost' (10061)")
 [in C:\xampp\htdocs\INFO\error_handlers.py:54]
2025-10-31 22:20:21,915 ERROR: Traceback (most recent call last):
  File "C:\xampp\htdocs\INFO\.venv\lib\site-packages\flask\app.py", line 915, in full_dispatch_request
    rv = self.preprocess_request()
  File "C:\xampp\htdocs\INFO\.venv\lib\site-packages\flask\app.py", line 1291, in preprocess_request
    rv = self.ensure_sync(before_func)()
  File "C:\xampp\htdocs\INFO\app.py", line 196, in before_request
    cur = mysql.connection.cursor()
  File "C:\xampp\htdocs\INFO\.venv\lib\site-packages\flask_mysqldb\__init__.py", line 109, in connection
    ctx.mysql_db = self.connect
  File "C:\xampp\htdocs\INFO\.venv\lib\site-packages\flask_mysqldb\__init__.py", line 97, in connect
    return MySQLdb.connect(**kwargs)
  File "C:\xampp\htdocs\INFO\.venv\lib\site-packages\MySQLdb\__init__.py", line 121, in Connect
    return Connection(*args, **kwargs)
  File "C:\xampp\htdocs\INFO\.venv\lib\site-packages\MySQLdb\connections.py", line 200, in __init__
    super().__init__(*args, **kwargs2)
MySQLdb.OperationalError: (2002, "Can't connect to server on 'localhost' (10061)")
 [in C:\xampp\htdocs\INFO\error_handlers.py:54]
2025-10-31 22:20:25,683 INFO: Accessing patient dashboard. Session data: {'_permanent': True, 'username': 'ahmed', 'role': 'patient', '_flashes': [('danger', 'An unexpected error occurred. Please try again later.')]} [in C:\xampp\htdocs\INFO\app.py:2108]
2025-10-31 22:20:25,683 INFO: Accessing patient dashboard. Session data: {'_permanent': True, 'username': 'ahmed', 'role': 'patient', '_flashes': [('danger', 'An unexpected error occurred. Please try again later.')]} [in C:\xampp\htdocs\INFO\app.py:2108]
2025-10-31 22:20:25,690 INFO: Successfully loaded dashboard for patient: ahmed [in C:\xampp\htdocs\INFO\app.py:2186]
2025-10-31 22:20:25,694 INFO: Successfully loaded dashboard for patient: ahmed [in C:\xampp\htdocs\INFO\app.py:2186]
