2025-10-31 14:57:29,942 ERROR: Traceback (most recent call last):
  File "C:\xampp\htdocs\INFO\.venv\lib\site-packages\flask\app.py", line 915, in full_dispatch_request
    rv = self.preprocess_request()
  File "C:\xampp\htdocs\INFO\.venv\lib\site-packages\flask\app.py", line 1291, in preprocess_request
    rv = self.ensure_sync(before_func)()
  File "C:\xampp\htdocs\INFO\app.py", line 184, in before_request
    cur = mysql.connection.cursor()
  File "C:\xampp\htdocs\INFO\.venv\lib\site-packages\flask_mysqldb\__init__.py", line 109, in connection
    ctx.mysql_db = self.connect
  File "C:\xampp\htdocs\INFO\.venv\lib\site-packages\flask_mysqldb\__init__.py", line 97, in connect
    return MySQLdb.connect(**kwargs)
  File "C:\xampp\htdocs\INFO\.venv\lib\site-packages\MySQLdb\__init__.py", line 121, in Connect
    return Connection(*args, **kwargs)
  File "C:\xampp\htdocs\INFO\.venv\lib\site-packages\MySQLdb\connections.py", line 200, in __init__
    super().__init__(*args, **kwargs2)
MySQLdb.OperationalError: (2002, "Can't connect to server on 'localhost' (10061)")
 [in C:\xampp\htdocs\INFO\error_handlers.py:54]
2025-10-31 14:57:34,074 ERROR: Unhandled Error: (2002, "Can't connect to server on 'localhost' (10061)") [in C:\xampp\htdocs\INFO\error_handlers.py:53]
2025-10-31 14:57:34,101 ERROR: Traceback (most recent call last):
  File "C:\xampp\htdocs\INFO\.venv\lib\site-packages\flask\app.py", line 915, in full_dispatch_request
    rv = self.preprocess_request()
  File "C:\xampp\htdocs\INFO\.venv\lib\site-packages\flask\app.py", line 1291, in preprocess_request
    rv = self.ensure_sync(before_func)()
  File "C:\xampp\htdocs\INFO\app.py", line 184, in before_request
    cur = mysql.connection.cursor()
  File "C:\xampp\htdocs\INFO\.venv\lib\site-packages\flask_mysqldb\__init__.py", line 109, in connection
    ctx.mysql_db = self.connect
  File "C:\xampp\htdocs\INFO\.venv\lib\site-packages\flask_mysqldb\__init__.py", line 97, in connect
    return MySQLdb.connect(**kwargs)
  File "C:\xampp\htdocs\INFO\.venv\lib\site-packages\MySQLdb\__init__.py", line 121, in Connect
    return Connection(*args, **kwargs)
  File "C:\xampp\htdocs\INFO\.venv\lib\site-packages\MySQLdb\connections.py", line 200, in __init__
    super().__init__(*args, **kwargs2)
MySQLdb.OperationalError: (2002, "Can't connect to server on 'localhost' (10061)")
 [in C:\xampp\htdocs\INFO\error_handlers.py:54]
2025-10-31 14:57:38,256 ERROR: Unhandled Error: (2002, "Can't connect to server on 'localhost' (10061)") [in C:\xampp\htdocs\INFO\error_handlers.py:53]
2025-10-31 14:57:38,276 ERROR: Traceback (most recent call last):
  File "C:\xampp\htdocs\INFO\.venv\lib\site-packages\flask\app.py", line 915, in full_dispatch_request
    rv = self.preprocess_request()
  File "C:\xampp\htdocs\INFO\.venv\lib\site-packages\flask\app.py", line 1291, in preprocess_request
    rv = self.ensure_sync(before_func)()
  File "C:\xampp\htdocs\INFO\app.py", line 184, in before_request
    cur = mysql.connection.cursor()
  File "C:\xampp\htdocs\INFO\.venv\lib\site-packages\flask_mysqldb\__init__.py", line 109, in connection
    ctx.mysql_db = self.connect
  File "C:\xampp\htdocs\INFO\.venv\lib\site-packages\flask_mysqldb\__init__.py", line 97, in connect
    return MySQLdb.connect(**kwargs)
  File "C:\xampp\htdocs\INFO\.venv\lib\site-packages\MySQLdb\__init__.py", line 121, in Connect
    return Connection(*args, **kwargs)
  File "C:\xampp\htdocs\INFO\.venv\lib\site-packages\MySQLdb\connections.py", line 200, in __init__
    super().__init__(*args, **kwargs2)
MySQLdb.OperationalError: (2002, "Can't connect to server on 'localhost' (10061)")
 [in C:\xampp\htdocs\INFO\error_handlers.py:54]
2025-10-31 14:57:42,394 ERROR: Unhandled Error: (2002, "Can't connect to server on 'localhost' (10061)") [in C:\xampp\htdocs\INFO\error_handlers.py:53]
2025-10-31 14:57:42,414 ERROR: Traceback (most recent call last):
  File "C:\xampp\htdocs\INFO\.venv\lib\site-packages\flask\app.py", line 915, in full_dispatch_request
    rv = self.preprocess_request()
  File "C:\xampp\htdocs\INFO\.venv\lib\site-packages\flask\app.py", line 1291, in preprocess_request
    rv = self.ensure_sync(before_func)()
  File "C:\xampp\htdocs\INFO\app.py", line 184, in before_request
    cur = mysql.connection.cursor()
  File "C:\xampp\htdocs\INFO\.venv\lib\site-packages\flask_mysqldb\__init__.py", line 109, in connection
    ctx.mysql_db = self.connect
  File "C:\xampp\htdocs\INFO\.venv\lib\site-packages\flask_mysqldb\__init__.py", line 97, in connect
    return MySQLdb.connect(**kwargs)
  File "C:\xampp\htdocs\INFO\.venv\lib\site-packages\MySQLdb\__init__.py", line 121, in Connect
    return Connection(*args, **kwargs)
  File "C:\xampp\htdocs\INFO\.venv\lib\site-packages\MySQLdb\connections.py", line 200, in __init__
    super().__init__(*args, **kwargs2)
MySQLdb.OperationalError: (2002, "Can't connect to server on 'localhost' (10061)")
 [in C:\xampp\htdocs\INFO\error_handlers.py:54]
2025-10-31 14:57:46,662 ERROR: Unhandled Error: (2002, "Can't connect to server on 'localhost' (10061)") [in C:\xampp\htdocs\INFO\error_handlers.py:53]
2025-10-31 14:57:46,698 ERROR: Traceback (most recent call last):
  File "C:\xampp\htdocs\INFO\.venv\lib\site-packages\flask\app.py", line 915, in full_dispatch_request
    rv = self.preprocess_request()
  File "C:\xampp\htdocs\INFO\.venv\lib\site-packages\flask\app.py", line 1291, in preprocess_request
    rv = self.ensure_sync(before_func)()
  File "C:\xampp\htdocs\INFO\app.py", line 184, in before_request
    cur = mysql.connection.cursor()
  File "C:\xampp\htdocs\INFO\.venv\lib\site-packages\flask_mysqldb\__init__.py", line 109, in connection
    ctx.mysql_db = self.connect
  File "C:\xampp\htdocs\INFO\.venv\lib\site-packages\flask_mysqldb\__init__.py", line 97, in connect
    return MySQLdb.connect(**kwargs)
  File "C:\xampp\htdocs\INFO\.venv\lib\site-packages\MySQLdb\__init__.py", line 121, in Connect
    return Connection(*args, **kwargs)
  File "C:\xampp\htdocs\INFO\.venv\lib\site-packages\MySQLdb\connections.py", line 200, in __init__
    super().__init__(*args, **kwargs2)
MySQLdb.OperationalError: (2002, "Can't connect to server on 'localhost' (10061)")
 [in C:\xampp\htdocs\INFO\error_handlers.py:54]
2025-10-31 14:57:47,899 INFO: Accessing patient dashboard. Session data: {'_permanent': True, 'username': 'ahmed', 'role': 'patient', '_flashes': [('danger', 'An unexpected error occurred. Please try again later.'), ('danger', 'An unexpected error occurred. Please try again later.'), ('danger', 'An unexpected error occurred. Please try again later.'), ('danger', 'An unexpected error occurred. Please try again later.'), ('danger', 'An unexpected error occurred. Please try again later.'), ('danger', 'An unexpected error occurred. Please try again later.'), ('danger', 'An unexpected error occurred. Please try again later.'), ('danger', 'An unexpected error occurred. Please try again later.'), ('danger', 'An unexpected error occurred. Please try again later.')]} [in C:\xampp\htdocs\INFO\app.py:2069]
2025-10-31 14:57:47,914 INFO: Successfully loaded dashboard for patient: ahmed [in C:\xampp\htdocs\INFO\app.py:2147]
2025-10-31 14:58:12,520 INFO: Accessing patient dashboard. Session data: {'_permanent': True, 'username': 'ahmed', 'role': 'patient'} [in C:\xampp\htdocs\INFO\app.py:2069]
2025-10-31 14:58:12,532 INFO: Successfully loaded dashboard for patient: ahmed [in C:\xampp\htdocs\INFO\app.py:2147]
2025-10-31 15:00:25,738 INFO: MRI analysis completed: Glioma, confidence: 0.934 [in C:\xampp\htdocs\INFO\app.py:2340]
2025-10-31 15:00:46,152 INFO: MRI analysis completed: Glioma, confidence: 0.95 [in C:\xampp\htdocs\INFO\app.py:2340]
2025-10-31 15:08:06,933 INFO: MRI analysis completed: Glioma, confidence: 0.958 [in C:\xampp\htdocs\INFO\app.py:2340]
2025-10-31 15:26:35,518 INFO: MRI analysis completed: Glioma, confidence: 0.988 [in C:\xampp\htdocs\INFO\app.py:2340]
2025-10-31 15:27:03,289 INFO: MRI analysis completed: Glioma, confidence: 0.934 [in C:\xampp\htdocs\INFO\app.py:2340]
2025-10-31 15:49:17,777 INFO: MRI analysis completed: Glioma, confidence: 0.934 [in C:\xampp\htdocs\INFO\app.py:2340]
2025-10-31 15:49:57,179 INFO: MRI analysis completed: Glioma, confidence: 0.934 [in C:\xampp\htdocs\INFO\app.py:2340]
2025-10-31 15:50:13,113 INFO: MRI analysis completed: Glioma, confidence: 0.995 [in C:\xampp\htdocs\INFO\app.py:2340]
2025-10-31 15:57:00,569 INFO: MRI analysis completed: Glioma, confidence: 0.563 [in C:\xampp\htdocs\INFO\app.py:2340]
2025-10-31 15:57:29,565 INFO: MRI analysis completed: Glioma, confidence: 0.851 [in C:\xampp\htdocs\INFO\app.py:2340]
2025-10-31 16:20:27,837 ERROR: Model file missing: Model file not found: C:\xampp\htdocs\INFO\model\mri_brain_tumor.h5
Please ensure the MRI brain tumor detection model is placed in: C:\xampp\htdocs\INFO\model
Expected file: mri_brain_tumor.h5 [in C:\xampp\htdocs\INFO\app.py:2342]
2025-10-31 16:20:27,848 ERROR: Traceback (most recent call last):
  File "C:\xampp\htdocs\INFO\app.py", line 2336, in patient_radiology
    result, conf = analyze_mri_image(stored_path)
  File "C:\xampp\htdocs\INFO\mri_analysis.py", line 76, in analyze_mri_image
    model = _get_model()
  File "C:\xampp\htdocs\INFO\mri_analysis.py", line 17, in _get_model
    raise FileNotFoundError(
FileNotFoundError: Model file not found: C:\xampp\htdocs\INFO\model\mri_brain_tumor.h5
Please ensure the MRI brain tumor detection model is placed in: C:\xampp\htdocs\INFO\model
Expected file: mri_brain_tumor.h5
 [in C:\xampp\htdocs\INFO\app.py:2343]
2025-10-31 16:23:02,081 ERROR: Error analyzing MRI image: Exception encountered when calling Flatten.call().

[1m'list' object has no attribute 'shape'[0m

Arguments received by Flatten.call():
  • args=(['<KerasTensor shape=(None, 4, 4, 512), dtype=float32, sparse=False, ragged=False, name=keras_tensor_37>'],)
  • kwargs=<class 'inspect._empty'> [in C:\xampp\htdocs\INFO\app.py:2346]
